<?xml version="1.0"?>
<robot name="four_wheeled_bot">

  <!-- Materials -->
  <material name="black">
    <color rgba="0 0 0 1"/>
  </material>

  <material name="silver">
    <color rgba="0.75 0.75 0.75 1"/>
  </material>

  <!-- Base link -->
  <link name="base_link">
    <inertial>
      <mass value="2.0"/>
      <origin xyz="0 0 0" rpy="0 0 0"/>
      <inertia ixx="0.01" ixy="0.0" ixz="0.0" iyy="0.02" iyz="0.0" izz="0.03"/>
    </inertial>
    <visual>
      <geometry>
        <box size="0.4 0.365 0.18"/>
      </geometry>
      <material name="silver"/>
    </visual>
    <collision>
      <geometry>
        <box size="0.4 0.365 0.18"/>
      </geometry>
    </collision>
  </link>

  <!-- Define four wheels with their links -->
  <!-- Front left wheel -->
  <link name="front_left_wheel">
    <inertial>
      <mass value="0.1"/>
      <origin xyz="0 0 0" rpy="0 0 0"/>
      <inertia ixx="0.00005" ixy="0.0" ixz="0.0" iyy="0.0001" iyz="0.0" izz="0.00005"/>
    </inertial>
    <visual>
      <geometry>
        <cylinder radius="0.055" length="0.04"/>
      </geometry>
      <material name="black"/>
    </visual>
    <collision>
      <geometry>
        <cylinder radius="0.055" length="0.04"/>
      </geometry>
    </collision>
  </link>

  <!-- Front right wheel -->
  <link name="front_right_wheel">
    <inertial>
      <mass value="0.1"/>
      <origin xyz="0 0 0" rpy="0 0 0"/>
      <inertia ixx="0.00005" ixy="0.0" ixz="0.0" iyy="0.0001" iyz="0.0" izz="0.00005"/>
    </inertial>
    <visual>
      <geometry>
        <cylinder radius="0.055" length="0.04"/>
      </geometry>
      <material name="black"/>
    </visual>
    <collision>
      <geometry>
        <cylinder radius="0.055" length="0.04"/>
      </geometry>
    </collision>
  </link>

  <!-- Rear left wheel -->
  <link name="rear_left_wheel">
    <inertial>
      <mass value="0.1"/>
      <origin xyz="0 0 0" rpy="0 0 0"/>
      <inertia ixx="0.00005" ixy="0.0" ixz="0.0" iyy="0.0001" iyz="0.0" izz="0.00005"/>
    </inertial>
    <visual>
      <geometry>
        <cylinder radius="0.055" length="0.04"/>
      </geometry>
      <material name="black"/>
    </visual>
    <collision>
      <geometry>
        <cylinder radius="0.055" length="0.04"/>
      </geometry>
    </collision>
  </link>

  <!-- Rear right wheel -->
  <link name="rear_right_wheel">
    <inertial>
      <mass value="0.1"/>
      <origin xyz="0 0 0" rpy="0 0 0"/>
      <inertia ixx="0.00005" ixy="0.0" ixz="0.0" iyy="0.0001" iyz="0.0" izz="0.00005"/>
    </inertial>
    <visual>
      <geometry>
        <cylinder radius="0.055" length="0.04"/>
      </geometry>
      <material name="black"/>
    </visual>
    <collision>
      <geometry>
        <cylinder radius="0.055" length="0.04"/>
      </geometry>
    </collision>
  </link>

  <!-- Joints -->
  <!-- Front left wheel joint -->
  <joint name="front_left_wheel_joint" type="continuous">
    <parent link="base_link"/>
    <child link="front_left_wheel"/>
    <origin xyz="-0.176 0.2025 -0.066" rpy="1.5708 1.5708 0"/>
    <axis xyz="0 0 1"/>
  </joint>

  <!-- Front right wheel joint -->
  <joint name="front_right_wheel_joint" type="continuous">
    <parent link="base_link"/>
    <child link="front_right_wheel"/>
    <origin xyz="-0.176 -0.2025 -0.066" rpy="1.5708 1.5708 0"/>
    <axis xyz="0 0 1"/>
  </joint>

  <!-- Rear left wheel joint -->
  <joint name="rear_left_wheel_joint" type="continuous">
    <parent link="base_link"/>
    <child link="rear_left_wheel"/>
    <origin xyz="0.176 0.2025 -0.066" rpy="1.5708 1.5708 0"/>
    <axis xyz="0 0 1"/>
  </joint>

  <!-- Rear right wheel joint -->
  <joint name="rear_right_wheel_joint" type="continuous">
    <parent link="base_link"/>
    <child link="rear_right_wheel"/>
    <origin xyz="0.176 -0.2025 -0.066" rpy="1.5708 1.5708 0"/>
    <axis xyz="0 0 1"/>
  </joint>

  <!-- Transmissions for ros2_control -->
  <transmission name="front_left_trans">
    <type>transmission_interface/SimpleTransmission</type>
    <joint name="front_left_wheel_joint">
      <hardwareInterface>hardware_interface/PositionJointInterface</hardwareInterface>
      <hardwareInterface>hardware_interface/VelocityJointInterface</hardwareInterface>
    </joint>
    <actuator name="front_left_motor">
      <mechanicalReduction>1</mechanicalReduction>
    </actuator>
  </transmission>

  <transmission name="front_right_trans">
    <type>transmission_interface/SimpleTransmission</type>
    <joint name="front_right_wheel_joint">
      <hardwareInterface>hardware_interface/PositionJointInterface</hardwareInterface>
      <hardwareInterface>hardware_interface/VelocityJointInterface</hardwareInterface>
    </joint>
    <actuator name="front_right_motor">
      <mechanicalReduction>1</mechanicalReduction>
    </actuator>
  </transmission>

  <transmission name="rear_left_trans">
    <type>transmission_interface/SimpleTransmission</type>
    <joint name="rear_left_wheel_joint">
      <hardwareInterface>hardware_interface/PositionJointInterface</hardwareInterface>
      <hardwareInterface>hardware_interface/VelocityJointInterface</hardwareInterface>
    </joint>
    <actuator name="rear_left_motor">
      <mechanicalReduction>1</mechanicalReduction>
    </actuator>
  </transmission>

  <transmission name="rear_right_trans">
    <type>transmission_interface/SimpleTransmission</type>
    <joint name="rear_right_wheel_joint">
      <hardwareInterface>hardware_interface/PositionJointInterface</hardwareInterface>
      <hardwareInterface>hardware_interface/VelocityJointInterface</hardwareInterface>
    </joint>
    <actuator name="rear_right_motor">
      <mechanicalReduction>1</mechanicalReduction>
    </actuator>
  </transmission>

</robot>